Workbook

Sheet MASTER
A1: NAT # | B1: Area, Bio, %, Time, Game | C1: Type 1 | D1: Type 2 | E1: LGPE | F1: SWSH | G1: BDSP | H1: BDSP | I1: SV | J1: ZA | K1: LGPE Location | L1: SWSH Location | M1: BDSP Location | N1: SV Location | O1: ZA Location | P1: LGPE Evolve | Q1: SWSH Evolve | R1: BDSP Evolve | S1: SV Evolve | T1: ZA Evolve | U1: Combined Evolve
A2: 1 | B2: Bulbasaur | C2: Grass | D2: Poison | E2: 001 | H2: 001 | J2: 148 | K2: Viridian Forest 👣 RARE | M2: Grassland Cave 👣 | O2: Wild Zone 20
A3: 2 | B3: Ivysaur | C3: Grass | D3: Poison | E3: 002 | H3: 002 | J3: 149 | K3: None | M3: None | O3: Evolve Only | P3: Bulbasaur (Lvl 16) | R3: Bulbasaur (Lvl 16) | T3: Bulbasaur (Lvl 16) | U3: Bulbasaur (Lvl 16)
A4: 3 | B4: Venusaur | C4: Grass | D4: Poison | E4: 003 | H4: 003 | J4: 150 | K4: None | M4: None | O4: Evolve Only | P4: Ivysaur (Lvl 32) | R4: Ivysaur (Lvl 32) | T4: Ivysaur (Lvl 32) | U4: Ivysaur (Lvl 32)
A5: 4 | B5: Charmander | C5: Fire | E5: 004 | F5: 378 | H5: 004 | J5: 151 | K5: Route 3 & 4 👣 RARE | L5: Hop's House | M5: Volcanic Cave 👣 | O5: Wild Zone 20
A6: 5 | B6: Charmeleon | C6: Fire | E6: 005 | F6: 379 | H6: 005 | J6: 152 | K6: None | L6: None | M6: None | O6: Evolve Only | P6: Charmander (Lvl 16) | Q6: Charmander (Lvl 16) | R6: Charmander (Lvl 16) | T6: Charmander (Lvl 16) | U6: Charmander (Lvl 16)
A7: 6 | B7: Charizard | C7: Fire | D7: Flying | E7: 006 | F7: 380 | H7: 006 | J7: 153 | K7: Route 6 – 19 🪽 RARE | L7: None | M7: None | O7: Evolve Only | P7: Charmeleon (Lvl 32) | Q7: Charmeleon (Lvl 36) | R7: Charmeleon (Lvl 32) | T7: Charmeleon (Lvl 32) | U7: Charmeleon (Lvl 32)
A8: 7 | B8: Squirtle | C8: Water | E8: 007 | H8: 007 | J8: 154 | K8: Route 24 & 25 👣 RARE | M8: Fountainspring Cave 👣 | O8: Side Mission 22 & Wild Zone 20
A9: 8 | B9: Wartortle | C9: Water | E9: 008 | H9: 008 | J9: 155 | K9: None | M9: None | O9: Evolve Only | P9: Squirtle (Lvl 16) | R9: Squirtle (Lvl 16) | T9: Squirtle (Lvl 16) | U9: Squirtle (Lvl 16)
A10: 9 | B10: Blastoise | C10: Water | E10: 009 | H10: 009 | J10: 156 | K10: None | M10: None | O10: Evolve Only | P10: Wartortle (Lvl 36) | R10: Wartortle (Lvl 36) | T10: Wartortle (Lvl 36) | U10: Wartortle (Lvl 36)
A11: 10 | B11: Caterpie | C11: Bug | E11: 010 | F11: 013 | H11: 010 | K11: Route 24 & 25 👣 RARE | L11: Route 1 🔍 | M11: Spacious Cave 👣 💎only
A12: 11 | B12: Metapod | C12: Bug | E12: 011 | F12: 014 | H12: 011 | K12: Viridian Forest 👣 | L12: Rolling Fields 👁️ | M12: None | P12: Caterpie (Lvl 7) | Q12: Caterpie (Lvl 7) | R12: Caterpie (Lvl 7) | U12: Caterpie (Lvl 7)
A13: 12 | B13: Butterfree | C13: Bug | D13: Flying | E13: 012 | F13: 015 | H13: 012 | K13: Viridian Forest 👣 ⚡only | L13: East Lake Axewell 👁️ | M13: None | P13: Metapod (Lvl 10) | Q13: Metapod (Lvl 10) | R13: Metapod (Lvl 10) | U13: Metapod (Lvl 10)
A14: 13 | B14: Weedle | C14: Bug | D14: Poison | E14: 013 | H14: 013 | J14: 018 | K14: Route 2 👣 | M14: Spacious Cave 👣 ⚪only | O14: Wild Zone 1
A15: 14 | B15: Kakuna | C15: Bug | D15: Poison | E15: 014 | H15: 014 | J15: 019 | K15: Viridian Forest 👣 | M15: None | O15: Wild Zone 2 | P15: Weedle (Lvl 7) | R15: Weedle (Lvl 7) | T15: Weedle (Lvl 7) | U15: Weedle (Lvl 7)
A16: 15 | B16: Beedrill | C16: Bug | D16: Poison | E16: 015 | H16: 015 | J16: 020 | K16: Viridian Forest 👣 🦊only | M16: None | O16: Wild Zone 15 ☀️ | P16: Kakuna (Lvl 10) | R16: Kakuna (Lvl 10) | T16: Kakuna (Lvl 10) | U16: Kakuna (Lvl 10)
A17: 16 | B17: Pidgey | C17: Normal | D17: Flying | E17: 016 | H17: 016 | J17: 021 | K17: Route 1 & 2 👣 | M17: Route 229 🐝 | O17: Wild Zones 1 & 5
A18: 17 | B18: Pidgeotto | C18: Normal | D18: Flying | E18: 017 | H18: 017 | J18: 022 | K18: Route 5 – 8 👣 | M18: None | O18: Wild Zone 5 | P18: Pidgey (Lvl 18) | R18: Pidgey (Lvl 18) | T18: Pidgey (Lvl 18) | U18: Pidgey (Lvl 18)
A19: 18 | B19: Pidgeot | C19: Normal | D19: Flying | E19: 018 | H19: 018 | J19: 023 | K19: Route 5 – 8 👣 | M19: None | O19: Bleu Sector 5 (On SW Roof) | P19: Pidgeotto (Lvl 36) | R19: Pidgeotto (Lvl 36) | T19: Pidgeotto (Lvl 36) | U19: Pidgeotto (Lvl 36)
A20: 19 | B20: Rattata | C20: Normal | E20: 019 | H20: 019 | K20: Route 1 – 11 👣 | M20: Spacious Cave 👣
A21: 20 | B21: Raticate | C21: Normal | E21: 020 | H21: 020 | K21: Route 7 – 11 👣 | M21: Spacious Cave 👣 | P21: Rattata (Lvl 20) | R21: Rattata (Lvl 20) | U21: Rattata (Lvl 20)
A22: 21 | B22: Spearow | C22: Normal | D22: Flying | E22: 021 | H22: 021 | K22: Route 3 & 4 👣 | M22: Spacious Cave 👣
A23: 22 | B23: Fearow | C23: Normal | D23: Flying | E23: 022 | H23: 022 | K23: Route 9 & 10 👣 | M23: Route 226 👣 🌅🏙️ | P23: Spearow (Lvl 20) | R23: Spearow (Lvl 20) | U23: Spearow (Lvl 20)
A24: 23 | B24: Ekans | C24: Poison | E24: 023 | H24: 023 | J24: 060 | K24: Route 3 & 4 👣 🦊only | M24: Grassland Cave 👣 💎only | O24: Wild Zone 4 ☀️
A25: 24 | B25: Arbok | C25: Poison | E25: 024 | H25: 024 | J25: 061 | K25: None | M25: None | O25: Evolve Only | P25: Ekans (Lvl 22) | R25: Ekans (Lvl 22) | T25: Ekans (Lvl 22) | U25: Ekans (Lvl 22)
A26: 25 | B26: Pikachu | C26: Electric | E26: 025 | F26: 194 | G26: 104 | H26: 025 | I26: 074 | J26: 053 | K26: Viridian Forest 👣 | L26: Rolling Fields ⚡ 📍 | M26: Trophy Garden 👣 20% | N26: South 2 & 4 🌲 10% | O26: Wild Zone 3 | Q26: Pichu (High Friendship) | R26: Pichu (High Friendship) | S26: Pichu (High Friendship) | T26: Pichu (High Friendship) | U26: Pichu (High Friendship)
A27: 26 | B27: Raichu | C27: Electric | E27: 026 | F27: 195 | G27: 105 | H27: 026 | I27: 075 | J27: 054 | K27: None | L27: None | M27: None | N27: Casseroya Lake 🌱 10% | O27: Evolve Only | P27: Pikachu (Thunder Stone) | Q27: Pikachu (Thunder Stone) | R27: Pikachu (Thunder Stone) | S27: Pikachu (Thunder Stone) | T27: Pikachu (Thunder Stone) | U27: Pikachu (Thunder Stone)
A28: 27 | B28: Sandshrew | C28: Ground | E28: 027 | H28: 027 | K28: Route 3 & 4 👣 ⚡only | M28: Spacious Cave 👣 ⚪only
A29: 28 | B29: Sandslash | C29: Ground | E29: 028 | H29: 028 | K29: None | M29: Spacious Cave 👣 ⚪only | P29: Sandshrew (Lvl 22) | R29: Sandshrew (Lvl 22) | U29: Sandshrew (Lvl 22)
A30: 29 | B30: Nidoran♀ | C30: Poison | E30: 029 | H30: 029 | K30: Route 9 & 10 👣 | M30: Grassland Cave 👣
A31: 30 | B31: Nidorina | C31: Poison | E31: 030 | H31: 030 | K31: Route 9 & 10 👣 | M31: Grassland Cave 👣 | P31: Nidoran♀ (Lvl 16) | R31: Nidoran♀ (Lvl 16) | U31: Nidoran♀ (Lvl 16)
A32: 31 | B32: Nidoqueen | C32: Poison | D32: Ground | E32: 031 | H32: 031 | K32: Route 23 👣 | M32: None | P32: Nidorina (Moon Stone) | R32: Nidorina (Moon Stone) | U32: Nidorina (Moon Stone)
A33: 32 | B33: Nidoran♂ | C33: Poison | E33: 032 | H33: 032 | K33: Route 9 & 10 👣 | M33: Grassland Cave 👣
A34: 33 | B34: Nidorino | C34: Poison | E34: 033 | H34: 033 | K34: Route 9 & 10 👣 | M34: Grassland Cave 👣 | P34: Nidoran♂ (Lvl 16) | R34: Nidoran♂ (Lvl 16) | U34: Nidoran♂ (Lvl 16)
A35: 34 | B35: Nidoking | C35: Poison | D35: Ground | E35: 034 | H35: 034 | K35: Route 23 👣 | M35: None | P35: Nidorino (Moon Stone) | R35: Nidorino (Moon Stone) | U35: Nidorino (Moon Stone)
A36: 35 | B36: Clefairy | C36: Fairy | E36: 035 | F36: 255 | G36: 100 | H36: 035 | J36: 056 | K36: Mt. Moon 👣 RARE | L36: Motostoke Outskirts 🌫️ 👁️ | M36: Mt. Coronet 2F 👣 15% 🌅 | O36: Wild Zone 19 ☀️ | Q36: Cleffa (High Friendship) | R36: Cleffa (High Friendship) | T36: Cleffa (High Friendship) | U36: Cleffa (High Friendship)
A37: 36 | B37: Clefable | C37: Fairy | E37: 036 | F37: 256 | G37: 101 | H37: 036 | J37: 057 | K37: Mt. Moon B2F 👣 | L37: Motostoke Riverbank 🌫️ 📍 | M37: None | O37: Evolve Only | P37: Clefairy (Moon Stone) | Q37: Clefairy (Moon Stone) | R37: Clefairy (Moon Stone) | T37: Clefairy (Moon Stone) | U37: Clefairy (Moon Stone)
A38: 37 | B38: Vulpix | C38: Fire | E38: 037 | F38: 068 | H38: 037 | K38: Route 5 – 8 👣 🦊only | L38: Lake of Outrage ☀️ 👁️ (🗡️only) | M38: Spacious Cave 👣 ⚪only
A39: 38 | B39: Ninetales | C39: Fire | E39: 038 | F39: 069 | H39: 038 | K39: Route 7 & 8 👣 🦊only | L39: Dusty Bowl ☀️ 👁️ | M39: None | P39: Vulpix (Fire Stone) | Q39: Vulpix (Fire Stone) | R39: Vulpix (Fire Stone) | U39: Vulpix (Fire Stone)
A40: 39 | B40: Jigglypuff | C40: Normal | D40: Fairy | E40: 039 | H40: 039 | I40: 060 | K40: Route 5 – 8 👣 | M40: Trophy Garden (Special) 👣 | N40: West 3 🏡 | R40: Igglybuff (High Friendship) | S40: Igglybuff (High Friendship) | U40: Igglybuff (High Friendship)
...

Sheet Sheet1
A1: ="{ id: """&MASTER!H2&"""" -> { id: "001" | B1: =" id2: """&MASTER!G2&"""" -> id2: "" | C1: =" name: """&MASTER!B2&"""" -> name: "Bulbasaur" | D1: =" img: """&LOWER(MID(C1,9,LEN(C1)-9))&".gif""" -> img: "bulbasaur.gif" | E1: =" type1: """&MASTER!C2&"""" -> type1: "Grass" | F1: =" type2: """&MASTER!D2&"""" -> type2: "Poison" | G1: =" location: """&_xlfn.TEXTJOIN(" ",1,TRIM(MASTER!M2))&"""" -> location: "Grassland Cave 👣" | H1: =" evolve: """&MASTER!#REF!&""" }" -> #REF! | I1: =_xlfn.TEXTJOIN(",",1,A1:H1)&"," -> #REF!
A2: ="{ id: """&MASTER!H3&"""" -> { id: "002" | B2: =" id2: """&MASTER!G3&"""" -> id2: "" | C2: =" name: """&MASTER!B3&"""" -> name: "Ivysaur" | D2: =" img: """&LOWER(MID(C2,9,LEN(C2)-9))&".gif""" -> img: "ivysaur.gif" | E2: =" type1: """&MASTER!C3&"""" -> type1: "Grass" | F2: =" type2: """&MASTER!D3&"""" -> type2: "Poison" | G2: =" location: """&_xlfn.TEXTJOIN(" ",1,TRIM(MASTER!M3))&"""" -> location: "None" | H2: =" evolve: """&MASTER!#REF!&""" }" -> #REF! | I2: =_xlfn.TEXTJOIN(",",1,A2:H2)&"," -> #REF!
A3: ="{ id: """&MASTER!H4&"""" -> { id: "003" | B3: =" id2: """&MASTER!G4&"""" -> id2: "" | C3: =" name: """&MASTER!B4&"""" -> name: "Venusaur" | D3: =" img: """&LOWER(MID(C3,9,LEN(C3)-9))&".gif""" -> img: "venusaur.gif" | E3: =" type1: """&MASTER!C4&"""" -> type1: "Grass" | F3: =" type2: """&MASTER!D4&"""" -> type2: "Poison" | G3: =" location: """&_xlfn.TEXTJOIN(" ",1,TRIM(MASTER!M4))&"""" -> location: "None" | H3: =" evolve: """&MASTER!#REF!&""" }" -> #REF! | I3: =_xlfn.TEXTJOIN(",",1,A3:H3)&"," -> #REF!
A4: ="{ id: """&MASTER!H5&"""" -> { id: "004" | B4: =" id2: """&MASTER!G5&"""" -> id2: "" | C4: =" name: """&MASTER!B5&"""" -> name: "Charmander" | D4: =" img: """&LOWER(MID(C4,9,LEN(C4)-9))&".gif""" -> img: "charmander.gif" | E4: =" type1: """&MASTER!C5&"""" -> type1: "Fire" | F4: =" type2: """&MASTER!D5&"""" -> type2: "" | G4: =" location: """&_xlfn.TEXTJOIN(" ",1,TRIM(MASTER!M5))&"""" -> location: "Volcanic Cave 👣" | H4: =" evolve: """&MASTER!#REF!&""" }" -> #REF! | I4: =_xlfn.TEXTJOIN(",",1,A4:H4)&"," -> #REF!
A5: ="{ id: """&MASTER!H6&"""" -> { id: "005" | B5: =" id2: """&MASTER!G6&"""" -> id2: "" | C5: =" name: """&MASTER!B6&"""" -> name: "Charmeleon" | D5: =" img: """&LOWER(MID(C5,9,LEN(C5)-9))&".gif""" -> img: "charmeleon.gif" | E5: =" type1: """&MASTER!C6&"""" -> type1: "Fire" | F5: =" type2: """&MASTER!D6&"""" -> type2: "" | G5: =" location: """&_xlfn.TEXTJOIN(" ",1,TRIM(MASTER!M6))&"""" -> location: "None" | H5: =" evolve: """&MASTER!#REF!&""" }" -> #REF! | I5: =_xlfn.TEXTJOIN(",",1,A5:H5)&"," -> #REF!
A6: ="{ id: """&MASTER!H7&"""" -> { id: "006" | B6: =" id2: """&MASTER!G7&"""" -> id2: "" | C6: =" name: """&MASTER!B7&"""" -> name: "Charizard" | D6: =" img: """&LOWER(MID(C6,9,LEN(C6)-9))&".gif""" -> img: "charizard.gif" | E6: =" type1: """&MASTER!C7&"""" -> type1: "Fire" | F6: =" type2: """&MASTER!D7&"""" -> type2: "Flying" | G6: =" location: """&_xlfn.TEXTJOIN(" ",1,TRIM(MASTER!M7))&"""" -> location: "None" | H6: =" evolve: """&MASTER!#REF!&""" }" -> #REF! | I6: =_xlfn.TEXTJOIN(",",1,A6:H6)&"," -> #REF!
A7: ="{ id: """&MASTER!H8&"""" -> { id: "007" | B7: =" id2: """&MASTER!G8&"""" -> id2: "" | C7: =" name: """&MASTER!B8&"""" -> name: "Squirtle" | D7: =" img: """&LOWER(MID(C7,9,LEN(C7)-9))&".gif""" -> img: "squirtle.gif" | E7: =" type1: """&MASTER!C8&"""" -> type1: "Water" | F7: =" type2: """&MASTER!D8&"""" -> type2: "" | G7: =" location: """&_xlfn.TEXTJOIN(" ",1,TRIM(MASTER!M8))&"""" -> location: "Fountainspring Cave 👣" | H7: =" evolve: """&MASTER!#REF!&""" }" -> #REF! | I7: =_xlfn.TEXTJOIN(",",1,A7:H7)&"," -> #REF!
A8: ="{ id: """&MASTER!H9&"""" -> { id: "008" | B8: =" id2: """&MASTER!G9&"""" -> id2: "" | C8: =" name: """&MASTER!B9&"""" -> name: "Wartortle" | D8: =" img: """&LOWER(MID(C8,9,LEN(C8)-9))&".gif""" -> img: "wartortle.gif" | E8: =" type1: """&MASTER!C9&"""" -> type1: "Water" | F8: =" type2: """&MASTER!D9&"""" -> type2: "" | G8: =" location: """&_xlfn.TEXTJOIN(" ",1,TRIM(MASTER!M9))&"""" -> location: "None" | H8: =" evolve: """&MASTER!#REF!&""" }" -> #REF! | I8: =_xlfn.TEXTJOIN(",",1,A8:H8)&"," -> #REF!
A9: ="{ id: """&MASTER!H10&"""" -> { id: "009" | B9: =" id2: """&MASTER!G10&"""" -> id2: "" | C9: =" name: """&MASTER!B10&"""" -> name: "Blastoise" | D9: =" img: """&LOWER(MID(C9,9,LEN(C9)-9))&".gif""" -> img: "blastoise.gif" | E9: =" type1: """&MASTER!C10&"""" -> type1: "Water" | F9: =" type2: """&MASTER!D10&"""" -> type2: "" | G9: =" location: """&_xlfn.TEXTJOIN(" ",1,TRIM(MASTER!M10))&"""" -> location: "None" | H9: =" evolve: """&MASTER!#REF!&""" }" -> #REF! | I9: =_xlfn.TEXTJOIN(",",1,A9:H9)&"," -> #REF!
A10: ="{ id: """&MASTER!H11&"""" -> { id: "010" | B10: =" id2: """&MASTER!G11&"""" -> id2: "" | C10: =" name: """&MASTER!B11&"""" -> name: "Caterpie" | D10: =" img: """&LOWER(MID(C10,9,LEN(C10)-9))&".gif""" -> img: "caterpie.gif" | E10: =" type1: """&MASTER!C11&"""" -> type1: "Bug" | F10: =" type2: """&MASTER!D11&"""" -> type2: "" | G10: =" location: """&_xlfn.TEXTJOIN(" ",1,TRIM(MASTER!M11))&"""" -> location: "Spacious Cave 👣 💎only" | H10: =" evolve: """&MASTER!#REF!&""" }" -> #REF! | I10: =_xlfn.TEXTJOIN(",",1,A10:H10)&"," -> #REF!
A11: ="{ id: """&MASTER!H12&"""" -> { id: "011" | B11: =" id2: """&MASTER!G12&"""" -> id2: "" | C11: =" name: """&MASTER!B12&"""" -> name: "Metapod" | D11: =" img: """&LOWER(MID(C11,9,LEN(C11)-9))&".gif""" -> img: "metapod.gif" | E11: =" type1: """&MASTER!C12&"""" -> type1: "Bug" | F11: =" type2: """&MASTER!D12&"""" -> type2: "" | G11: =" location: """&_xlfn.TEXTJOIN(" ",1,TRIM(MASTER!M12))&"""" -> location: "None" | H11: =" evolve: """&MASTER!#REF!&""" }" -> #REF! | I11: =_xlfn.TEXTJOIN(",",1,A11:H11)&"," -> #REF!
A12: ="{ id: """&MASTER!H13&"""" -> { id: "012" | B12: =" id2: """&MASTER!G13&"""" -> id2: "" | C12: =" name: """&MASTER!B13&"""" -> name: "Butterfree" | D12: =" img: """&LOWER(MID(C12,9,LEN(C12)-9))&".gif""" -> img: "butterfree.gif" | E12: =" type1: """&MASTER!C13&"""" -> type1: "Bug" | F12: =" type2: """&MASTER!D13&"""" -> type2: "Flying" | G12: =" location: """&_xlfn.TEXTJOIN(" ",1,TRIM(MASTER!M13))&"""" -> location: "None" | H12: =" evolve: """&MASTER!#REF!&""" }" -> #REF! | I12: =_xlfn.TEXTJOIN(",",1,A12:H12)&"," -> #REF!
... A493: ="{ id: """&MASTER!H494&"""" -> { id: "493" | B493: =" id2: """&MASTER!G494&"""" -> id2: "" | C493: =" name: """&MASTER!B494&"""" -> name: "Arceus" | D493: =" img: """&LOWER(MID(C493,9,LEN(C493)-9))&".gif""" -> img: "arceus.gif" | E493: =" type1: """&MASTER!C494&"""" -> type1: "Normal" | F493: =" type2: """&MASTER!D494&"""" -> type2: "" | G493: =" location: """&_xlfn.TEXTJOIN(" ",1,TRIM(MASTER!M494))&"""" -> location: "Special Instructions" | H493: =" evolve: """&MASTER!#REF!&""" }" -> #REF! | I493: =_xlfn.TEXTJOIN(",",1,A493:H493)&"," -> #REF!
